[2022-06-08 22:19:04,356] {taskinstance.py:876} INFO - Dependencies all met for <TaskInstance: say_hi.greeting_task 2022-06-06T00:00:00+00:00 [queued]>
[2022-06-08 22:19:04,383] {taskinstance.py:876} INFO - Dependencies all met for <TaskInstance: say_hi.greeting_task 2022-06-06T00:00:00+00:00 [queued]>
[2022-06-08 22:19:04,383] {taskinstance.py:1067} INFO - 
--------------------------------------------------------------------------------
[2022-06-08 22:19:04,383] {taskinstance.py:1068} INFO - Starting attempt 1 of 2
[2022-06-08 22:19:04,387] {taskinstance.py:1069} INFO - 
--------------------------------------------------------------------------------
[2022-06-08 22:19:04,400] {taskinstance.py:1087} INFO - Executing <Task(PythonOperator): greeting_task> on 2022-06-06T00:00:00+00:00
[2022-06-08 22:19:04,407] {standard_task_runner.py:52} INFO - Started process 2003 to run task
[2022-06-08 22:19:04,412] {standard_task_runner.py:76} INFO - Running: ['***', 'tasks', 'run', 'say_hi', 'greeting_task', '2022-06-06T00:00:00+00:00', '--job-id', '51', '--pool', 'default_pool', '--raw', '--subdir', 'DAGS_FOLDER/username.py', '--cfg-path', '/tmp/tmpkdsof539', '--error-file', '/tmp/tmprv9n7i3e']
[2022-06-08 22:19:04,413] {standard_task_runner.py:77} INFO - Job 51: Subtask greeting_task
[2022-06-08 22:19:04,468] {logging_mixin.py:104} INFO - Running <TaskInstance: say_hi.greeting_task 2022-06-06T00:00:00+00:00 [running]> on host 69873a4b1233
[2022-06-08 22:19:04,564] {taskinstance.py:1282} INFO - Exporting the following env vars:
AIRFLOW_CTX_DAG_OWNER=***
AIRFLOW_CTX_DAG_ID=say_hi
AIRFLOW_CTX_TASK_ID=greeting_task
AIRFLOW_CTX_EXECUTION_DATE=2022-06-06T00:00:00+00:00
AIRFLOW_CTX_DAG_RUN_ID=scheduled__2022-06-06T00:00:00+00:00
[2022-06-08 22:19:04,568] {taskinstance.py:1481} ERROR - Task failed with exception
Traceback (most recent call last):
  File "/home/airflow/.local/lib/python3.6/site-packages/airflow/models/taskinstance.py", line 1137, in _run_raw_task
    self._prepare_and_execute_task_with_callbacks(context, task)
  File "/home/airflow/.local/lib/python3.6/site-packages/airflow/models/taskinstance.py", line 1311, in _prepare_and_execute_task_with_callbacks
    result = self._execute_task(context, task_copy)
  File "/home/airflow/.local/lib/python3.6/site-packages/airflow/models/taskinstance.py", line 1341, in _execute_task
    result = task_copy.execute(context=context)
  File "/home/airflow/.local/lib/python3.6/site-packages/airflow/operators/python.py", line 150, in execute
    return_value = self.execute_callable()
  File "/home/airflow/.local/lib/python3.6/site-packages/airflow/operators/python.py", line 161, in execute_callable
    return self.python_callable(*self.op_args, **self.op_kwargs)
  File "/opt/airflow/dags/username.py", line 17, in print_hello
    with open("./username.txt") as f:
FileNotFoundError: [Errno 2] No such file or directory: './username.txt'
[2022-06-08 22:19:04,571] {taskinstance.py:1531} INFO - Marking task as UP_FOR_RETRY. dag_id=say_hi, task_id=greeting_task, execution_date=20220606T000000, start_date=20220608T221904, end_date=20220608T221904
[2022-06-08 22:19:04,626] {local_task_job.py:151} INFO - Task exited with return code 1
